Workbook
Name Slicer_Assigned_Team: #N/A
Name Slicer_Business_Unit: #N/A
Name Slicer_Channel: #N/A

Sheet Data_Quality
A1: Data Quality Check | B1: Result
A2: Total Rows | B2: =ROWS(tbl_Operations[Ticket_ID]) -> 5000
A3: Total Columns | B3: =COLUMNS(tbl_Operations[]) -> 28
A4: Duplicate Ticket IDs | B4: =ROWS(tbl_Operations[Ticket_ID])-ROWS(_xlfn.UNIQUE(tbl_Operations[Ticket_ID])) -> 0
A5: Blank Locations | B5: =COUNTBLANK(tbl_Operations[Location]) -> 0
A6: Blank Request Types | B6: =COUNTBLANK(tbl_Operations[Request_Type]) -> 0
A7: Blank Channels | B7: =COUNTBLANK(tbl_Operations[Channel]) -> 0
A8: Blank Assigned Teams | B8: =COUNTBLANK(tbl_Operations[Assigned_Team]) -> 0
A9: Blank CSAT | B9: =COUNTBLANK(tbl_Operations[Customer_Satisfaction]) -> 0

Sheet Pivot_Resolution
A5: Business Unit | B5: Average Resolution Hrs
A6: Customer Support | B6: 12.984154
A7: Finance | B7: 12.862665
A8: HR | B8: 12.486719
A9: IT | B9: 12.914825
A10: Operations | B10: 12.927066
A11: Procurement | B11: 13.109986
A12: Sales | B12: 12.274559
A13: Grand Total | B13: 12.79436

Sheet Pivot_SLA
B3: Column Labels
B4: SLA Breach | D4: Within SLA | F4: Total Count of Ticket_ID | G4: Total Within SLA%
A5: Row Labels | B5: Count of Ticket_ID | C5: Within SLA% | D5: Count of Ticket_ID | E5: Within SLA%
A6: Customer Support | B6: 117 | C6: 0.15579228 | D6: 634 | E6: 0.84420772 | F6: 751 | G6: 1
A7: Finance | B7: 99 | C7: 0.14494876 | D7: 584 | E7: 0.85505124 | F7: 683 | G7: 1
A8: Hr | B8: 97 | C8: 0.12630208 | D8: 671 | E8: 0.87369792 | F8: 768 | G8: 1
A9: It | B9: 108 | C9: 0.15104895 | D9: 607 | E9: 0.84895105 | F9: 715 | G9: 1
A10: Operations | B10: 104 | C10: 0.14814815 | D10: 598 | E10: 0.85185185 | F10: 702 | G10: 1
A11: Procurement | B11: 109 | C11: 0.15549215 | D11: 592 | E11: 0.84450785 | F11: 701 | G11: 1
A12: Sales | B12: 96 | C12: 0.14117647 | D12: 584 | E12: 0.85882353 | F12: 680 | G12: 1
A13: Grand Total | B13: 730 | C13: 0.146 | D13: 4270 | E13: 0.854 | F13: 5000 | G13: 1

Sheet SLA_Chart_Data   
A1: Business Unit | B1: SLA Achievement %
A2: Customer Support | B2: =_xlfn.XLOOKUP(A2,Pivot_SLA!$A$6:$A$12,Pivot_SLA!$E$6:$E$12,"Not Found") -> 0.84420772
A3: Finance | B3: =_xlfn.XLOOKUP(A3,Pivot_SLA!$A$6:$A$12,Pivot_SLA!$E$6:$E$12,"Not Found") -> 0.85505124
A4: HR | B4: =_xlfn.XLOOKUP(A4,Pivot_SLA!$A$6:$A$12,Pivot_SLA!$E$6:$E$12,"Not Found") -> 0.87369792
A5: IT | B5: =_xlfn.XLOOKUP(A5,Pivot_SLA!$A$6:$A$12,Pivot_SLA!$E$6:$E$12,"Not Found") -> 0.84895105
A6: Operations | B6: =_xlfn.XLOOKUP(A6,Pivot_SLA!$A$6:$A$12,Pivot_SLA!$E$6:$E$12,"Not Found") -> 0.85185185
A7: Procurement | B7: =_xlfn.XLOOKUP(A7,Pivot_SLA!$A$6:$A$12,Pivot_SLA!$E$6:$E$12,"Not Found") -> 0.84450785
A8: Sales | B8: =_xlfn.XLOOKUP(A8,Pivot_SLA!$A$6:$A$12,Pivot_SLA!$E$6:$E$12,"Not Found") -> 0.85882353

Sheet Pivot_Monthly
A3: Row Labels | B3: Count of Ticket_ID
A4: Jan | B4: 420
A5: Feb | B5: 392
A6: Mar | B6: 404
A7: Apr | B7: 433
A8: May | B8: 441
A9: Jun | B9: 440
A10: Jul | B10: 375
A11: Aug | B11: 441
A12: Sep | B12: 395
A13: Oct | B13: 418
A14: Nov | B14: 411
A15: Dec | B15: 430
A16: Grand Total | B16: 5000

Sheet Pivot_Rework
B3: Column Labels
B4: No Rework | D4: Reworked | F4: Total Count of Ticket_ID | G4: Total Count of Ticket_ID2
A5: Row Labels | B5: Count of Ticket_ID | C5: Count of Ticket_ID2 | D5: Count of Ticket_ID | E5: Count of Ticket_ID2
A6: Customer Support | B6: 419 | C6: 0.55792277 | D6: 332 | E6: 0.44207723 | F6: 751 | G6: 1
A7: Finance | B7: 372 | C7: 0.54465593 | D7: 311 | E7: 0.45534407 | F7: 683 | G7: 1
A8: Hr | B8: 450 | C8: 0.5859375 | D8: 318 | E8: 0.4140625 | F8: 768 | G8: 1
A9: It | B9: 408 | C9: 0.57062937 | D9: 307 | E9: 0.42937063 | F9: 715 | G9: 1
A10: Operations | B10: 393 | C10: 0.55982906 | D10: 309 | E10: 0.44017094 | F10: 702 | G10: 1
A11: Procurement | B11: 391 | C11: 0.55777461 | D11: 310 | E11: 0.44222539 | F11: 701 | G11: 1
A12: Sales | B12: 396 | C12: 0.58235294 | D12: 284 | E12: 0.41764706 | F12: 680 | G12: 1
A13: Grand Total | B13: 2829 | C13: 0.5658 | D13: 2171 | E13: 0.4342 | F13: 5000 | G13: 1
A17: Business Unit | B17: Rework Ticket Rate
A18: Customer Support | B18: =_xlfn.XLOOKUP(A18,$A$6:$A$12,$E$6:$E$12,,0) -> 0.44207723
A19: Finance | B19: =_xlfn.XLOOKUP(A19,$A$6:$A$12,$E$6:$E$12,,0) -> 0.45534407
A20: HR | B20: =_xlfn.XLOOKUP(A20,$A$6:$A$12,$E$6:$E$12,,0) -> 0.4140625
A21: IT | B21: =_xlfn.XLOOKUP(A21,$A$6:$A$12,$E$6:$E$12,,0) -> 0.42937063
A22: Operations | B22: =_xlfn.XLOOKUP(A22,$A$6:$A$12,$E$6:$E$12,,0) -> 0.44017094
A23: Procurement | B23: =_xlfn.XLOOKUP(A23,$A$6:$A$12,$E$6:$E$12,,0) -> 0.44222539
A24: Sales | B24: =_xlfn.XLOOKUP(A24,$A$6:$A$12,$E$6:$E$12,,0) -> 0.41764706

Sheet Pivot_Cost
A3: Row Labels | B3: Total Cost
A4: Customer Support | B4: 3509593 | D4: Business Unit | E4: Total Cost | F4: Tickets | G4: Cost per Ticket
A5: Finance | B5: 3161483 | D5: Customer Support | E5: =_xlfn.XLOOKUP(D5,A4:A10,B4:B10,,0) -> 3509593 | F5: =COUNTIF(tbl_Operations[Business_Unit],D5) -> 751 | G5: =E5/F5 -> 4673.2264
A6: Hr | B6: 3446642 | D6: Finance | E6: =_xlfn.XLOOKUP(D6,A5:A11,B5:B11,,0) -> 3161483 | F6: =COUNTIF(tbl_Operations[Business_Unit],D6) -> 683 | G6: =E6/F6 -> 4628.8184
A7: It | B7: 3301070 | D7: HR | E7: =_xlfn.XLOOKUP(D7,A6:A12,B6:B12,,0) -> 3446642 | F7: =COUNTIF(tbl_Operations[Business_Unit],D7) -> 768 | G7: =E7/F7 -> 4487.8151
A8: Operations | B8: 3299592 | D8: IT | E8: =_xlfn.XLOOKUP(D8,A7:A13,B7:B13,,0) -> 3301070 | F8: =COUNTIF(tbl_Operations[Business_Unit],D8) -> 715 | G8: =E8/F8 -> 4616.8811
A9: Procurement | B9: 3326307 | D9: Operations | E9: =_xlfn.XLOOKUP(D9,A8:A14,B8:B14,,0) -> 3299592 | F9: =COUNTIF(tbl_Operations[Business_Unit],D9) -> 702 | G9: =E9/F9 -> 4700.2735
A10: Sales | B10: 2997714 | D10: Procurement | E10: =_xlfn.XLOOKUP(D10,A9:A15,B9:B15,,0) -> 3326307 | F10: =COUNTIF(tbl_Operations[Business_Unit],D10) -> 701 | G10: =E10/F10 -> 4745.0884
A11: Grand Total | B11: 23042401 | D11: Sales | E11: =_xlfn.XLOOKUP(D11,A10:A16,B10:B16,,0) -> 2997714 | F11: =COUNTIF(tbl_Operations[Business_Unit],D11) -> 680 | G11: =E11/F11 -> 4408.4029

Sheet Raw_Data
A1: Ticket_ID | B1: Ticket_Date | C1: Business_Unit | D1: Location | E1: Request_Type | F1: Priority | G1: Channel | H1: Assigned_Team | I1: Status | J1: Resolution_Hours | K1: SLA_Target_Hours | L1: SLA_Breached | M1: Rework_Count | N1: Customer_Satisfaction | O1: FTE_Cost_per_Hour | P1: Estimated_Cost | Q1: Month | R1: Month_No | S1: Quarter | T1: Weekday | U1: Location_Clean | V1: Channel_Clean | W1: Request_Type_Clean | X1: Business_Unit_Clean | Y1: SLA_Status | Z1: Critical_SLA_Risk | AA1: Performance_Band | AB1: Rework_Status
A2: OPS-101659 | B2: 45817 | C2: Customer Support | D2: Noida | E2: Invoice Query | F2: Medium | G2: Email | H2: Vendor Management | I2: Closed | J2: 2.5 | K2: 24 | L2: No | M2: 0 | N2: 4.3 | O2: 350 | P2: 875 | Q2: Jun | R2: 6 | S2: Q2 | T2: Monday | U2: =TRIM(CLEAN(tbl_Operations[[#This Row],[Location]])) -> Noida | V2: =TRIM(CLEAN(tbl_Operations[[#This Row],[Channel]])) -> Email | W2: =TRIM(CLEAN(E2)) -> Invoice Query | X2: =PROPER(TRIM(CLEAN(C2))) -> Customer Support | Y2: =IF(J2<=K2,"Within SLA","SLA Breach") -> Within SLA | Z2: =IF(AND(F2="Critical",Y1="SLA Breach"),"Critical Risk","Normal") -> Normal | AA2: {=_xlfn.IFS( J2<=K2*0.5,"Excellent", J2<=K2,"Good", J2<=K2*1.5,"At Risk", TRUE,"Critical" )} -> Excellent | AB2: =IF(M2>0,"Reworked","No Rework") -> No Rework
A3: OPS-100733 | B3: 45874 | C3: IT | D3: Mumbai | E3: Employee Query | F3: Medium | G3: Email | H3: Vendor Management | I3: Closed | J3: 20.2 | K3: 24 | L3: No | M3: 0 | N3: 4.6 | O3: 350 | P3: 7070 | Q3: Aug | R3: 8 | S3: Q3 | T3: Tuesday | U3: =TRIM(CLEAN(tbl_Operations[[#This Row],[Location]])) -> Mumbai | V3: =TRIM(CLEAN(tbl_Operations[[#This Row],[Channel]])) -> Email | W3: =TRIM(CLEAN(E3)) -> Employee Query | X3: =PROPER(TRIM(CLEAN(C3))) -> It | Y3: =IF(J3<=K3,"Within SLA","SLA Breach") -> Within SLA | Z3: =IF(AND(F3="Critical",Y2="SLA Breach"),"Critical Risk","Normal") -> Normal | AA3: {=_xlfn.IFS( J3<=K3*0.5,"Excellent", J3<=K3,"Good", J3<=K3*1.5,"At Risk", TRUE,"Critical" )} -> Good | AB3: =IF(M3>0,"Reworked","No Rework") -> No Rework
A4: OPS-103875 | B4: 45800 | C4: Procurement | D4: Bengaluru | E4: Invoice Query | F4: Medium | G4: Portal | H4: MIS | I4: Closed | J4: 5.4 | K4: 24 | L4: No | M4: 0 | N4: 5 | O4: 280 | P4: 1512 | Q4: May | R4: 5 | S4: Q2 | T4: Friday | U4: =TRIM(CLEAN(tbl_Operations[[#This Row],[Location]])) -> Bengaluru | V4: =TRIM(CLEAN(tbl_Operations[[#This Row],[Channel]])) -> Portal | W4: =TRIM(CLEAN(E4)) -> Invoice Query | X4: =PROPER(TRIM(CLEAN(C4))) -> Procurement | Y4: =IF(J4<=K4,"Within SLA","SLA Breach") -> Within SLA | Z4: =IF(AND(F4="Critical",Y2="SLA Breach"),"Critical Risk","Normal") -> Normal | AA4: {=_xlfn.IFS( J4<=K4*0.5,"Excellent", J4<=K4,"Good", J4<=K4*1.5,"At Risk", TRUE,"Critical" )} -> Excellent | AB4: =IF(M4>0,"Reworked","No Rework") -> No Rework
A5: OPS-101335 | B5: 45950 | C5: Procurement | D5: Gurugram | E5: Compliance Request | F5: Low | G5: Portal | H5: HR Ops | I5: Closed | J5: 8.1 | K5: 48 | L5: No | M5: 0 | N5: 4.8 | O5: 450 | P5: 3645 | Q5: Oct | R5: 10 | S5: Q4 | T5: Monday | U5: =TRIM(CLEAN(tbl_Operations[[#This Row],[Location]])) -> Gurugram | V5: =TRIM(CLEAN(tbl_Operations[[#This Row],[Channel]])) -> Portal | W5: =TRIM(CLEAN(E5)) -> Compliance Request | X5: =PROPER(TRIM(CLEAN(C5))) -> Procurement | Y5: =IF(J5<=K5,"Within SLA","SLA Breach") -> Within SLA | Z5: =IF(AND(F5="Critical",Y4="SLA Breach"),"Critical Risk","Normal") -> Normal | AA5: {=_xlfn.IFS( J5<=K5*0.5,"Excellent", J5<=K5,"Good", J5<=K5*1.5,"At Risk", TRUE,"Critical" )} -> Excellent | AB5: =IF(M5>0,"Reworked","No Rework") -> No Rework
A6: OPS-103608 | B6: 45702 | C6: HR | D6: Hyderabad | E6: Vendor Query | F6: Medium | G6: Email | H6: HR Ops | I6: Closed | J6: 1.8 | K6: 24 | L6: No | M6: 0 | N6: 4.9 | O6: 350 | P6: 630 | Q6: Feb | R6: 2 | S6: Q1 | T6: Friday | U6: =TRIM(CLEAN(tbl_Operations[[#This Row],[Location]])) -> Hyderabad | V6: =TRIM(CLEAN(tbl_Operations[[#This Row],[Channel]])) -> Email | W6: =TRIM(CLEAN(E6)) -> Vendor Query | X6: =PROPER(TRIM(CLEAN(C6))) -> Hr | Y6: =IF(J6<=K6,"Within SLA","SLA Breach") -> Within SLA | Z6: =IF(AND(F6="Critical",Y5="SLA Breach"),"Critical Risk","Normal") -> Normal | AA6: {=_xlfn.IFS( J6<=K6*0.5,"Excellent", J6<=K6,"Good", J6<=K6*1.5,"At Risk", TRUE,"Critical" )} -> Excellent | AB6: =IF(M6>0,"Reworked","No Rework") -> No Rework
A7: OPS-101008 | B7: 45670 | C7: Procurement | D7: Pune | E7: Employee Query | F7: High | G7: Teams | H7: MIS | I7: Closed | J7: 16.8 | K7: 12 | L7: Yes | M7: 1 | N7: 4 | O7: 450 | P7: 7560 | Q7: Jan | R7: 1 | S7: Q1 | T7: Monday | U7: =TRIM(CLEAN(tbl_Operations[[#This Row],[Location]])) -> Pune | V7: =TRIM(CLEAN(tbl_Operations[[#This Row],[Channel]])) -> Teams | W7: =TRIM(CLEAN(E7)) -> Employee Query | X7: =PROPER(TRIM(CLEAN(C7))) -> Procurement | Y7: =IF(J7<=K7,"Within SLA","SLA Breach") -> SLA Breach | Z7: =IF(AND(F7="Critical",Y6="SLA Breach"),"Critical Risk","Normal") -> Normal | AA7: {=_xlfn.IFS( J7<=K7*0.5,"Excellent", J7<=K7,"Good", J7<=K7*1.5,"At Risk", TRUE,"Critical" )} -> At Risk | AB7: =IF(M7>0,"Reworked","No Rework") -> Reworked
A8: OPS-102746 | B8: 45962 | C8: Procurement | D8: Mumbai | E8: Invoice Query | F8: Low | G8: Teams | H8: IT Support | I8: Closed | J8: 9.5 | K8: 48 | L8: No | M8: 0 | N8: 4.6 | O8: 350 | P8: 3325 | Q8: Nov | R8: 11 | S8: Q4 | T8: Saturday | U8: =TRIM(CLEAN(tbl_Operations[[#This Row],[Location]])) -> Mumbai | V8: =TRIM(CLEAN(tbl_Operations[[#This Row],[Channel]])) -> Teams | W8: =TRIM(CLEAN(E8)) -> Invoice Query | X8: =PROPER(TRIM(CLEAN(C8))) -> Procurement | Y8: =IF(J8<=K8,"Within SLA","SLA Breach") -> Within SLA | Z8: =IF(AND(F8="Critical",Y7="SLA Breach"),"Critical Risk","Normal") -> Normal | AA8: {=_xlfn.IFS( J8<=K8*0.5,"Excellent", J8<=K8,"Good", J8<=K8*1.5,"At Risk", TRUE,"Critical" )} -> Excellent | AB8: =IF(M8>0,"Reworked","No Rework") -> No Rework
A9: OPS-103424 | B9: 46014 | C9: IT | D9: Mumbai | E9: Data Correction | F9: High | G9: Email | H9: IT Support | I9: Closed | J9: 20 | K9: 12 | L9: Yes | M9: 0 | N9: 4.3 | O9: 320 | P9: 6400 | Q9: Dec | R9: 12 | S9: Q4 | T9: Tuesday | U9: =TRIM(CLEAN(tbl_Operations[[#This Row],[Location]])) -> Mumbai | V9: =TRIM(CLEAN(tbl_Operations[[#This Row],[Channel]])) -> Email | W9: =TRIM(CLEAN(E9)) -> Data Correction | X9: =PROPER(TRIM(CLEAN(C9))) -> It | Y9: =IF(J9<=K9,"Within SLA","SLA Breach") -> SLA Breach | Z9: =IF(AND(F9="Critical",Y8="SLA Breach"),"Critical Risk","Normal") -> Normal | AA9: {=_xlfn.IFS( J9<=K9*0.5,"Excellent", J9<=K9,"Good", J9<=K9*1.5,"At Risk", TRUE,"Critical" )} -> Critical | AB9: =IF(M9>0,"Reworked","No Rework") -> No Rework
A10: OPS-102847 | B10: 45874 | C10: IT | D10: Chennai | E10: System Issue | F10: Medium | G10: Email | H10: Finance Ops | I10: Closed | J10: 14 | K10: 24 | L10: No | M10: 0 | N10: 4.7 | O10: 450 | P10: 6300 | Q10: Aug | R10: 8 | S10: Q3 | T10: Tuesday | U10: =TRIM(CLEAN(tbl_Operations[[#This Row],[Location]])) -> Chennai | V10: =TRIM(CLEAN(tbl_Operations[[#This Row],[Channel]])) -> Email | W10: =TRIM(CLEAN(E10)) -> System Issue | X10: =PROPER(TRIM(CLEAN(C10))) -> It | Y10: =IF(J10<=K10,"Within SLA","SLA Breach") -> Within SLA | Z10: =IF(AND(F10="Critical",Y9="SLA Breach"),"Critical Risk","Normal") -> Normal | AA10: {=_xlfn.IFS( J10<=K10*0.5,"Excellent", J10<=K10,"Good", J10<=K10*1.5,"At Risk", TRUE,"Critical" )} -> Good | AB10: =IF(M10>0,"Reworked","No Rework") -> No Rework
A11: OPS-103077 | B11: 45724 | C11: Finance | D11: Mumbai | E11: Access Request | F11: High | G11: Email | H11: Finance Ops | I11: Closed | J11: 2.1 | K11: 12 | L11: No | M11: 0 | N11: 5 | O11: 280 | P11: 588 | Q11: Mar | R11: 3 | S11: Q1 | T11: Saturday | U11: =TRIM(CLEAN(tbl_Operations[[#This Row],[Location]])) -> Mumbai | V11: =TRIM(CLEAN(tbl_Operations[[#This Row],[Channel]])) -> Email | W11: =TRIM(CLEAN(E11)) -> Access Request | X11: =PROPER(TRIM(CLEAN(C11))) -> Finance | Y11: =IF(J11<=K11,"Within SLA","SLA Breach") -> Within SLA | Z11: =IF(AND(F11="Critical",Y10="SLA Breach"),"Critical Risk","Normal") -> Normal | AA11: {=_xlfn.IFS( J11<=K11*0.5,"Excellent", J11<=K11,"Good", J11<=K11*1.5,"At Risk", TRUE,"Critical" )} -> Excellent | AB11: =IF(M11>0,"Reworked","No Rework") -> No Rework
A12: OPS-100168 | B12: 45997 | C12: Finance | D12: Bengaluru | E12: System Issue | F12: Medium | G12: Phone | H12: IT Support | I12: Closed | J12: 19.6 | K12: 24 | L12: No | M12: 1 | N12: 4.2 | O12: 320 | P12: 6272 | Q12: Dec | R12: 12 | S12: Q4 | T12: Saturday | U12: =TRIM(CLEAN(tbl_Operations[[#This Row],[Location]])) -> Bengaluru | V12: =TRIM(CLEAN(tbl_Operations[[#This Row],[Channel]])) -> Phone | W12: =TRIM(CLEAN(E12)) -> System Issue | X12: =PROPER(TRIM(CLEAN(C12))) -> Finance | Y12: =IF(J12<=K12,"Within SLA","SLA Breach") -> Within SLA | Z12: =IF(AND(F12="Critical",Y11="SLA Breach"),"Critical Risk","Normal") -> Normal | AA12: {=_xlfn.IFS( J12<=K12*0.5,"Excellent", J12<=K12,"Good", J12<=K12*1.5,"At Risk", TRUE,"Critical" )} -> Good | AB12: =IF(M12>0,"Reworked","No Rework") -> Reworked
A13: OPS-104875 | B13: 45925 | C13: Procurement | D13: Chennai | E13: Vendor Query | F13: Medium | G13: Email | H13: Vendor Management | I13: Closed | J13: 28.1 | K13: 24 | L13: Yes | M13: 0 | N13: 4.2 | O13: 450 | P13: 12645 | Q13: Sep | R13: 9 | S13: Q3 | T13: Thursday | U13: =TRIM(CLEAN(tbl_Operations[[#This Row],[Location]])) -> Chennai | V13: =TRIM(CLEAN(tbl_Operations[[#This Row],[Channel]])) -> Email | W13: =TRIM(CLEAN(E13)) -> Vendor Query | X13: =PROPER(TRIM(CLEAN(C13))) -> Procurement | Y13: =IF(J13<=K13,"Within SLA","SLA Breach") -> SLA Breach | Z13: =IF(AND(F13="Critical",Y12="SLA Breach"),"Critical Risk","Normal") -> Normal | AA13: {=_xlfn.IFS( J13<=K13*0.5,"Excellent", J13<=K13,"Good", J13<=K13*1.5,"At Risk", TRUE,"Critical" )} -> At Risk | AB13: =IF(M13>0,"Reworked","No Rework") -> No Rework
A14: OPS-101376 | B14: 45686 | C14: HR | D14: Bengaluru | E14: Compliance Request | F14: High | G14: Email | H14: HR Ops | I14: Closed | J14: 11.9 | K14: 12 | L14: No | M14: 2 | N14: 4.2 | O14: 400 | P14: 4760 | Q14: Jan | R14: 1 | S14: Q1 | T14: Wednesday | U14: =TRIM(CLEAN(tbl_Operations[[#This Row],[Location]])) -> Bengaluru | V14: =TRIM(CLEAN(tbl_Operations[[#This Row],[Channel]])) -> Email | W14: =TRIM(CLEAN(E14)) -> Compliance Request | X14: =PROPER(TRIM(CLEAN(C14))) -> Hr | Y14: =IF(J14<=K14,"Within SLA","SLA Breach") -> Within SLA | Z14: =IF(AND(F14="Critical",Y13="SLA Breach"),"Critical Risk","Normal") -> Normal | AA14: {=_xlfn.IFS( J14<=K14*0.5,"Excellent", J14<=K14,"Good", J14<=K14*1.5,"At Risk", TRUE,"Critical" )} -> Good | AB14: =IF(M14>0,"Reworked","No Rework") -> Reworked
A15: OPS-104728 | B15: 45749 | C15: Procurement | D15: Gurugram | E15: Data Correction | F15: Low | G15: Phone | H15: MIS | I15: Escalated | J15: 5.4 | K15: 48 | L15: No | M15: 1 | N15: 5 | O15: 320 | P15: 1728 | Q15: Apr | R15: 4 | S15: Q2 | T15: Wednesday | U15: =TRIM(CLEAN(tbl_Operations[[#This Row],[Location]])) -> Gurugram | V15: =TRIM(CLEAN(tbl_Operations[[#This Row],[Channel]])) -> Phone | W15: =TRIM(CLEAN(E15)) -> Data Correction | X15: =PROPER(TRIM(CLEAN(C15))) -> Procurement | Y15: =IF(J15<=K15,"Within SLA","SLA Breach") -> Within SLA | Z15: =IF(AND(F15="Critical",Y14="SLA Breach"),"Critical Risk","Normal") -> Normal | AA15: {=_xlfn.IFS( J15<=K15*0.5,"Excellent", J15<=K15,"Good", J15<=K15*1.5,"At Risk", TRUE,"Critical" )} -> Excellent | AB15: =IF(M15>0,"Reworked","No Rework") -> Reworked
A16: OPS-100834 | B16: 46009 | C16: Operations | D16: Mumbai | E16: Report Request | F16: Medium | G16: Portal | H16: Finance Ops | I16: Closed | J16: 20.7 | K16: 24 | L16: No | M16: 0 | N16: 3.8 | O16: 320 | P16: 6624 | Q16: Dec | R16: 12 | S16: Q4 | T16: Thursday | U16: =TRIM(CLEAN(tbl_Operations[[#This Row],[Location]])) -> Mumbai | V16: =TRIM(CLEAN(tbl_Operations[[#This Row],[Channel]])) -> Portal | W16: =TRIM(CLEAN(E16)) -> Report Request | X16: =PROPER(TRIM(CLEAN(C16))) -> Operations | Y16: =IF(J16<=K16,"Within SLA","SLA Breach") -> Within SLA | Z16: =IF(AND(F16="Critical",Y15="SLA Breach"),"Critical Risk","Normal") -> Normal | AA16: {=_xlfn.IFS( J16<=K16*0.5,"Excellent", J16<=K16,"Good", J16<=K16*1.5,"At Risk", TRUE,"Critical" )} -> Good | AB16: =IF(M16>0,"Reworked","No Rework") -> No Rework
... A386: OPS-101115 | B386: 45772 | C386: Finance | D386: Mumbai | E386: Compliance Request | F386: Medium | G386: Email | H386: Finance Ops | I386: Pending | J386: 8.2 | K386: 24 | L386: No | M386: 0 | N386: 5 | O386: 320 | P386: 2624 | Q386: Apr | R386: 4 | S386: Q2 | T386: Friday | U386: =TRIM(CLEAN(tbl_Operations[[#This Row],[Location]])) -> Mumbai | V386: =TRIM(CLEAN(tbl_Operations[[#This Row],[Channel]])) -> Email | W386: =TRIM(CLEAN(E386)) -> Compliance Request | X386: =PROPER(TRIM(CLEAN(C386))) -> Finance | Y386: =IF(J386<=K386,"Within SLA","SLA Breach") -> Within SLA | Z386: =IF(AND(F386="Critical",Y385="SLA Breach"),"Critical Risk","Normal") -> Normal | AA386: {=_xlfn.IFS( J386<=K386*0.5,"Excellent", J386<=K386,"Good", J386<=K386*1.5,"At Risk", TRUE,"Critical" )} -> Excellent | AB386: =IF(M386>0,"Reworked","No Rework") -> No Rework
A387: OPS-101926 | B387: 45992 | C387: IT | D387: Gurugram | E387: Vendor Query | F387: Medium | G387: Teams | H387: Finance Ops | I387: Closed | J387: 18 | K387: 24 | L387: No | M387: 1 | N387: Unknown | O387: 450 | P387: 8100 | Q387: Dec | R387: 12 | S387: Q4 | T387: Monday | U387: =TRIM(CLEAN(tbl_Operations[[#This Row],[Location]])) -> Gurugram | V387: =TRIM(CLEAN(tbl_Operations[[#This Row],[Channel]])) -> Teams | W387: =TRIM(CLEAN(E387)) -> Vendor Query | X387: =PROPER(TRIM(CLEAN(C387))) -> It | Y387: =IF(J387<=K387,"Within SLA","SLA Breach") -> Within SLA | Z387: =IF(AND(F387="Critical",Y386="SLA Breach"),"Critical Risk","Normal") -> Normal | AA387: {=_xlfn.IFS( J387<=K387*0.5,"Excellent", J387<=K387,"Good", J387<=K387*1.5,"At Risk", TRUE,"Critical" )} -> Good | AB387: =IF(M387>0,"Reworked","No Rework") -> Reworked
A388: OPS-102537 | B388: 45736 | C388: Operations | D388: Gurugram | E388: Employee Query | F388: High | G388: Teams | H388: IT Support | I388: Escalated | J388: 31.3 | K388: 12 | L388: Yes | M388: 1 | N388: 3.8 | O388: 350 | P388: 10955 | Q388: Mar | R388: 3 | S388: Q1 | T388: Thursday | U388: =TRIM(CLEAN(tbl_Operations[[#This Row],[Location]])) -> Gurugram | V388: =TRIM(CLEAN(tbl_Operations[[#This Row],[Channel]])) -> Teams | W388: =TRIM(CLEAN(E388)) -> Employee Query | X388: =PROPER(TRIM(CLEAN(C388))) -> Operations | Y388: =IF(J388<=K388,"Within SLA","SLA Breach") -> SLA Breach | Z388: =IF(AND(F388="Critical",Y387="SLA Breach"),"Critical Risk","Normal") -> Normal | AA388: {=_xlfn.IFS( J388<=K388*0.5,"Excellent", J388<=K388,"Good", J388<=K388*1.5,"At Risk", TRUE,"Critical" )} -> Critical | AB388: =IF(M388>0,"Reworked","No Rework") -> Reworked
A389: OPS-101408 | B389: 45953 | C389: HR | D389: Mumbai | E389: Invoice Query | F389: Low | G389: Phone | H389: Vendor Management | I389: Closed | J389: 0.9 | K389: 48 | L389: No | M389: 1 | N389: 4.5 | O389: 320 | P389: 288 | Q389: Oct | R389: 10 | S389: Q4 | T389: Thursday | U389: =TRIM(CLEAN(tbl_Operations[[#This Row],[Location]])) -> Mumbai | V389: =TRIM(CLEAN(tbl_Operations[[#This Row],[Channel]])) -> Phone | W389: =TRIM(CLEAN(E389)) -> Invoice Query | X389: =PROPER(TRIM(CLEAN(C389))) -> Hr | Y389: =IF(J389<=K389,"Within SLA","SLA Breach") -> Within SLA | Z389: =IF(AND(F389="Critical",Y388="SLA Breach"),"Critical Risk","Normal") -> Normal | AA389: {=_xlfn.IFS( J389<=K389*0.5,"Excellent", J389<=K389,"Good", J389<=K389*1.5,"At Risk", TRUE,"Critical" )} -> Excellent | AB389: =IF(M389>0,"Reworked","No Rework") -> Reworked
A390: OPS-101432 | B390: 45968 | C390: Customer Support | D390: Gurugram | E390: Employee Query | F390: Medium | G390: Teams | H390: Finance Ops | I390: Closed | J390: 4.4 | K390: 24 | L390: No | M390: 0 | N390: 5 | O390: 350 | P390: 1540 | Q390: Nov | R390: 11 | S390: Q4 | T390: Friday | U390: =TRIM(CLEAN(tbl_Operations[[#This Row],[Location]])) -> Gurugram | V390: =TRIM(CLEAN(tbl_Operations[[#This Row],[Channel]])) -> Teams | W390: =TRIM(CLEAN(E390)) -> Employee Query | X390: =PROPER(TRIM(CLEAN(C390))) -> Customer Support | Y390: =IF(J390<=K390,"Within SLA","SLA Breach") -> Within SLA | Z390: =IF(AND(F390="Critical",Y389="SLA Breach"),"Critical Risk","Normal") -> Normal | AA390: {=_xlfn.IFS( J390<=K390*0.5,"Excellent", J390<=K390,"Good", J390<=K390*1.5,"At Risk", TRUE,"Critical" )} -> Excellent | AB390: =IF(M390>0,"Reworked","No Rework") -> No Rework
A391: OPS-100793 | B391: 45755 | C391: Sales | D391: Mumbai | E391: Compliance Request | F391: Medium | G391: Portal | H391: MIS | I391: Closed | J391: 8.3 | K391: 24 | L391: No | M391: 1 | N391: 4.9 | O391: 280 | P391: 2324 | Q391: Apr | R391: 4 | S391: Q2 | T391: Tuesday | U391: =TRIM(CLEAN(tbl_Operations[[#This Row],[Location]])) -> Mumbai | V391: =TRIM(CLEAN(tbl_Operations[[#This Row],[Channel]])) -> Portal | W391: =TRIM(CLEAN(E391)) -> Compliance Request | X391: =PROPER(TRIM(CLEAN(C391))) -> Sales | Y391: =IF(J391<=K391,"Within SLA","SLA Breach") -> Within SLA | Z391: =IF(AND(F391="Critical",Y390="SLA Breach"),"Critical Risk","Normal") -> Normal | AA391: {=_xlfn.IFS( J391<=K391*0.5,"Excellent", J391<=K391,"Good", J391<=K391*1.5,"At Risk", TRUE,"Critical" )} -> Excellent | AB391: =IF(M391>0,"Reworked","No Rework") -> Reworked
A392: OPS-103921 | B392: 45703 | C392: HR | D392: Mumbai | E392: Employee Query | F392: High | G392: Portal | H392: IT Support | I392: Pending | J392: 6.7 | K392: 12 | L392: No | M392: 1 | N392: 4.4 | O392: 350 | P392: 2345 | Q392: Feb | R392: 2 | S392: Q1 | T392: Saturday | U392: =TRIM(CLEAN(tbl_Operations[[#This Row],[Location]])) -> Mumbai | V392: =TRIM(CLEAN(tbl_Operations[[#This Row],[Channel]])) -> Portal | W392: =TRIM(CLEAN(E392)) -> Employee Query | X392: =PROPER(TRIM(CLEAN(C392))) -> Hr | Y392: =IF(J392<=K392,"Within SLA","SLA Breach") -> Within SLA | Z392: =IF(AND(F392="Critical",Y391="SLA Breach"),"Critical Risk","Normal") -> Normal | AA392: {=_xlfn.IFS( J392<=K392*0.5,"Excellent", J392<=K392,"Good", J392<=K392*1.5,"At Risk", TRUE,"Critical" )} -> Good | AB392: =IF(M392>0,"Reworked","No Rework") -> Reworked
A393: OPS-104457 | B393: 45915 | C393: Sales | D393: Hyderabad | E393: Access Request | F393: High | G393: Email | H393: HR Ops | I393: Closed | J393: 4.1 | K393: 12 | L393: No | M393: 1 | N393: 5 | O393: 280 | P393: 1148 | Q393: Sep | R393: 9 | S393: Q3 | T393: Monday | U393: =TRIM(CLEAN(tbl_Operations[[#This Row],[Location]])) -> Hyderabad | V393: =TRIM(CLEAN(tbl_Operations[[#This Row],[Channel]])) -> Email | W393: =TRIM(CLEAN(E393)) -> Access Request | X393: =PROPER(TRIM(CLEAN(C393))) -> Sales | Y393: =IF(J393<=K393,"Within SLA","SLA Breach") -> Within SLA | Z393: =IF(AND(F393="Critical",Y392="SLA Breach"),"Critical Risk","Normal") -> Normal | AA393: {=_xlfn.IFS( J393<=K393*0.5,"Excellent", J393<=K393,"Good", J393<=K393*1.5,"At Risk", TRUE,"Critical" )} -> Excellent | AB393: =IF(M393>0,"Reworked","No Rework") -> Reworked
A394: OPS-104655 | B394: 45687 | C394: Procurement | D394: Pune | E394: Access Request | F394: Medium | G394: Email | H394: MIS | I394: Closed | J394: 7.6 | K394: 24 | L394: No | M394: 0 | N394: 4.7 | O394: 400 | P394: 3040 | Q394: Jan | R394: 1 | S394: Q1 | T394: Thursday | U394: =TRIM(CLEAN(tbl_Operations[[#This Row],[Location]])) -> Pune | V394: =TRIM(CLEAN(tbl_Operations[[#This Row],[Channel]])) -> Email | W394: =TRIM(CLEAN(E394)) -> Access Request | X394: =PROPER(TRIM(CLEAN(C394))) -> Procurement | Y394: =IF(J394<=K394,"Within SLA","SLA Breach") -> Within SLA | Z394: =IF(AND(F394="Critical",Y393="SLA Breach"),"Critical Risk","Normal") -> Normal | AA394: {=_xlfn.IFS( J394<=K394*0.5,"Excellent", J394<=K394,"Good", J394<=K394*1.5,"At Risk", TRUE,"Critical" )} -> Excellent | AB394: =IF(M394>0,"Reworked","No Rework") -> No Rework
A395: OPS-102475 | B395: 45840 | C395: Procurement | D395: Bengaluru | E395: Vendor Query | F395: High | G395: Email | H395: Vendor Management | I395: Closed | J395: 13.2 | K395: 12 | L395: Yes | M395: 0 | N395: 4.4 | O395: 350 | P395: 4620 | Q395: Jul | R395: 7 | S395: Q3 | T395: Wednesday | U395: =TRIM(CLEAN(tbl_Operations[[#This Row],[Location]])) -> Bengaluru | V395: =TRIM(CLEAN(tbl_Operations[[#This Row],[Channel]])) -> Email | W395: =TRIM(CLEAN(E395)) -> Vendor Query | X395: =PROPER(TRIM(CLEAN(C395))) -> Procurement | Y395: =IF(J395<=K395,"Within SLA","SLA Breach") -> SLA Breach | Z395: =IF(AND(F395="Critical",Y394="SLA Breach"),"Critical Risk","Normal") -> Normal | AA395: {=_xlfn.IFS( J395<=K395*0.5,"Excellent", J395<=K395,"Good", J395<=K395*1.5,"At Risk", TRUE,"Critical" )} -> At Risk | AB395: =IF(M395>0,"Reworked","No Rework") -> No Rework
A396: OPS-104083 | B396: 45936 | C396: Sales | D396: Bengaluru | E396: Report Request | F396: Medium | G396: Teams | H396: MIS | I396: Pending | J396: 6.1 | K396: 24 | L396: No | M396: 0 | N396: 5 | O396: 320 | P396: 1952 | Q396: Oct | R396: 10 | S396: Q4 | T396: Monday | U396: =TRIM(CLEAN(tbl_Operations[[#This Row],[Location]])) -> Bengaluru | V396: =TRIM(CLEAN(tbl_Operations[[#This Row],[Channel]])) -> Teams | W396: =TRIM(CLEAN(E396)) -> Report Request | X396: =PROPER(TRIM(CLEAN(C396))) -> Sales | Y396: =IF(J396<=K396,"Within SLA","SLA Breach") -> Within SLA | Z396: =IF(AND(F396="Critical",Y395="SLA Breach"),"Critical Risk","Normal") -> Normal | AA396: {=_xlfn.IFS( J396<=K396*0.5,"Excellent", J396<=K396,"Good", J396<=K396*1.5,"At Risk", TRUE,"Critical" )} -> Excellent | AB396: =IF(M396>0,"Reworked","No Rework") -> No Rework
A397: OPS-104459 | B397: 46020 | C397: IT | D397: Hyderabad | E397: Invoice Query | F397: Low | G397: Email | H397: Vendor Management | I397: Closed | J397: 13.3 | K397: 48 | L397: No | M397: 1 | N397: 4.3 | O397: 350 | P397: 4655 | Q397: Dec | R397: 12 | S397: Q4 | T397: Monday | U397: =TRIM(CLEAN(tbl_Operations[[#This Row],[Location]])) -> Hyderabad | V397: =TRIM(CLEAN(tbl_Operations[[#This Row],[Channel]])) -> Email | W397: =TRIM(CLEAN(E397)) -> Invoice Query | X397: =PROPER(TRIM(CLEAN(C397))) -> It | Y397: =IF(J397<=K397,"Within SLA","SLA Breach") -> Within SLA | Z397: =IF(AND(F397="Critical",Y396="SLA Breach"),"Critical Risk","Normal") -> Normal | AA397: {=_xlfn.IFS( J397<=K397*0.5,"Excellent", J397<=K397,"Good", J397<=K397*1.5,"At Risk", TRUE,"Critical" )} -> Excellent | AB397: =IF(M397>0,"Reworked","No Rework") -> Reworked
A398: OPS-101591 | B398: 45780 | C398: Finance | D398: Gurugram | E398: System Issue | F398: High | G398: Phone | H398: MIS | I398: Closed | J398: 25.9 | K398: 12 | L398: Yes | M398: 0 | N398: 4.3 | O398: 400 | P398: 10360 | Q398: May | R398: 5 | S398: Q2 | T398: Saturday | U398: =TRIM(CLEAN(tbl_Operations[[#This Row],[Location]])) -> Gurugram | V398: =TRIM(CLEAN(tbl_Operations[[#This Row],[Channel]])) -> Phone | W398: =TRIM(CLEAN(E398)) -> System Issue | X398: =PROPER(TRIM(CLEAN(C398))) -> Finance | Y398: =IF(J398<=K398,"Within SLA","SLA Breach") -> SLA Breach | Z398: =IF(AND(F398="Critical",Y397="SLA Breach"),"Critical Risk","Normal") -> Normal | AA398: {=_xlfn.IFS( J398<=K398*0.5,"Excellent", J398<=K398,"Good", J398<=K398*1.5,"At Risk", TRUE,"Critical" )} -> Critical | AB398: =IF(M398>0,"Reworked","No Rework") -> No Rework
A399: OPS-103277 | B399: 45825 | C399: Operations | D399: Bengaluru | E399: System Issue | F399: Low | G399: Portal | H399: Finance Ops | I399: Closed | J399: 17.2 | K399: 48 | L399: No | M399: 0 | N399: 4.7 | O399: 350 | P399: 6020 | Q399: Jun | R399: 6 | S399: Q2 | T399: Tuesday | U399: =TRIM(CLEAN(tbl_Operations[[#This Row],[Location]])) -> Bengaluru | V399: =TRIM(CLEAN(tbl_Operations[[#This Row],[Channel]])) -> Portal | W399: =TRIM(CLEAN(E399)) -> System Issue | X399: =PROPER(TRIM(CLEAN(C399))) -> Operations | Y399: =IF(J399<=K399,"Within SLA","SLA Breach") -> Within SLA | Z399: =IF(AND(F399="Critical",Y398="SLA Breach"),"Critical Risk","Normal") -> Normal | AA399: {=_xlfn.IFS( J399<=K399*0.5,"Excellent", J399<=K399,"Good", J399<=K399*1.5,"At Risk", TRUE,"Critical" )} -> Excellent | AB399: =IF(M399>0,"Reworked","No Rework") -> No Rework
... A582: OPS-101338 | B582: 45803 | C582: Finance | D582: Hyderabad | E582: Data Correction | F582: High | G582: Portal | H582: MIS | I582: Closed | J582: 8.7 | K582: 12 | L582: No | M582: 1 | N582: 4.9 | O582: 450 | P582: 3915 | Q582: May | R582: 5 | S582: Q2 | T582: Monday | U582: =TRIM(CLEAN(tbl_Operations[[#This Row],[Location]])) -> Hyderabad | V582: =TRIM(CLEAN(tbl_Operations[[#This Row],[Channel]])) -> Portal | W582: =TRIM(CLEAN(E582)) -> Data Correction | X582: =PROPER(TRIM(CLEAN(C582))) -> Finance | Y582: =IF(J582<=K582,"Within SLA","SLA Breach") -> Within SLA | Z582: =IF(AND(F582="Critical",Y581="SLA Breach"),"Critical Risk","Normal") -> Normal | AA582: {=_xlfn.IFS( J582<=K582*0.5,"Excellent", J582<=K582,"Good", J582<=K582*1.5,"At Risk", TRUE,"Critical" )} -> Good | AB582: =IF(M582>0,"Reworked","No Rework") -> Reworked
A583: OPS-104101 | B583: 45846 | C583: Customer Support | D583: Hyderabad | E583: Employee Query | F583: Low | G583: Phone | H583: Finance Ops | I583: Closed | J583: 33.5 | K583: 48 | L583: No | M583: 0 | N583: Unknown | O583: 320 | P583: 10720 | Q583: Jul | R583: 7 | S583: Q3 | T583: Tuesday | U583: =TRIM(CLEAN(tbl_Operations[[#This Row],[Location]])) -> Hyderabad | V583: =TRIM(CLEAN(tbl_Operations[[#This Row],[Channel]])) -> Phone | W583: =TRIM(CLEAN(E583)) -> Employee Query | X583: =PROPER(TRIM(CLEAN(C583))) -> Customer Support | Y583: =IF(J583<=K583,"Within SLA","SLA Breach") -> Within SLA | Z583: =IF(AND(F583="Critical",Y582="SLA Breach"),"Critical Risk","Normal") -> Normal | AA583: {=_xlfn.IFS( J583<=K583*0.5,"Excellent", J583<=K583,"Good", J583<=K583*1.5,"At Risk", TRUE,"Critical" )} -> Good | AB583: =IF(M583>0,"Reworked","No Rework") -> No Rework
A584: OPS-102111 | B584: 45733 | C584: Operations | D584: Mumbai | E584: Vendor Query | F584: Low | G584: Teams | H584: Finance Ops | I584: Closed | J584: 7.4 | K584: 48 | L584: No | M584: 0 | N584: 4.2 | O584: 400 | P584: 2960 | Q584: Mar | R584: 3 | S584: Q1 | T584: Monday | U584: =TRIM(CLEAN(tbl_Operations[[#This Row],[Location]])) -> Mumbai | V584: =TRIM(CLEAN(tbl_Operations[[#This Row],[Channel]])) -> Teams | W584: =TRIM(CLEAN(E584)) -> Vendor Query | X584: =PROPER(TRIM(CLEAN(C584))) -> Operations | Y584: =IF(J584<=K584,"Within SLA","SLA Breach") -> Within SLA | Z584: =IF(AND(F584="Critical",Y583="SLA Breach"),"Critical Risk","Normal") -> Normal | AA584: {=_xlfn.IFS( J584<=K584*0.5,"Excellent", J584<=K584,"Good", J584<=K584*1.5,"At Risk", TRUE,"Critical" )} -> Excellent | AB584: =IF(M584>0,"Reworked","No Rework") -> No Rework
A585: OPS-102546 | B585: 45857 | C585: Procurement | D585: Mumbai | E585: Invoice Query | F585: High | G585: Email | H585: IT Support | I585: Closed | J585: 4.5 | K585: 12 | L585: No | M585: 1 | N585: 5 | O585: 280 | P585: 1260 | Q585: Jul | R585: 7 | S585: Q3 | T585: Saturday | U585: =TRIM(CLEAN(tbl_Operations[[#This Row],[Location]])) -> Mumbai | V585: =TRIM(CLEAN(tbl_Operations[[#This Row],[Channel]])) -> Email | W585: =TRIM(CLEAN(E585)) -> Invoice Query | X585: =PROPER(TRIM(CLEAN(C585))) -> Procurement | Y585: =IF(J585<=K585,"Within SLA","SLA Breach") -> Within SLA | Z585: =IF(AND(F585="Critical",Y584="SLA Breach"),"Critical Risk","Normal") -> Normal | AA585: {=_xlfn.IFS( J585<=K585*0.5,"Excellent", J585<=K585,"Good", J585<=K585*1.5,"At Risk", TRUE,"Critical" )} -> Excellent | AB585: =IF(M585>0,"Reworked","No Rework") -> Reworked
A586: OPS-104121 | B586: 45845 | C586: Finance | D586: Noida | E586: System Issue | F586: Low | G586: Email | H586: MIS | I586: Closed | J586: 14.9 | K586: 48 | L586: No | M586: 2 | N586: 4.5 | O586: 280 | P586: 4172 | Q586: Jul | R586: 7 | S586: Q3 | T586: Monday | U586: =TRIM(CLEAN(tbl_Operations[[#This Row],[Location]])) -> Noida | V586: =TRIM(CLEAN(tbl_Operations[[#This Row],[Channel]])) -> Email | W586: =TRIM(CLEAN(E586)) -> System Issue | X586: =PROPER(TRIM(CLEAN(C586))) -> Finance | Y586: =IF(J586<=K586,"Within SLA","SLA Breach") -> Within SLA | Z586: =IF(AND(F586="Critical",Y585="SLA Breach"),"Critical Risk","Normal") -> Normal | AA586: {=_xlfn.IFS( J586<=K586*0.5,"Excellent", J586<=K586,"Good", J586<=K586*1.5,"At Risk", TRUE,"Critical" )} -> Excellent | AB586: =IF(M586>0,"Reworked","No Rework") -> Reworked
A587: OPS-103033 | B587: 45870 | C587: HR | D587: Noida | E587: Employee Query | F587: Medium | G587: Portal | H587: HR Ops | I587: Closed | J587: 11.1 | K587: 24 | L587: No | M587: 1 | N587: 5 | O587: 350 | P587: 3885 | Q587: Aug | R587: 8 | S587: Q3 | T587: Friday | U587: =TRIM(CLEAN(tbl_Operations[[#This Row],[Location]])) -> Noida | V587: =TRIM(CLEAN(tbl_Operations[[#This Row],[Channel]])) -> Portal | W587: =TRIM(CLEAN(E587)) -> Employee Query | X587: =PROPER(TRIM(CLEAN(C587))) -> Hr | Y587: =IF(J587<=K587,"Within SLA","SLA Breach") -> Within SLA | Z587: =IF(AND(F587="Critical",Y586="SLA Breach"),"Critical Risk","Normal") -> Normal | AA587: {=_xlfn.IFS( J587<=K587*0.5,"Excellent", J587<=K587,"Good", J587<=K587*1.5,"At Risk", TRUE,"Critical" )} -> Excellent | AB587: =IF(M587>0,"Reworked","No Rework") -> Reworked
A588: OPS-100501 | B588: 45904 | C588: IT | D588: Noida | E588: System Issue | F588: High | G588: Portal | H588: Finance Ops | I588: Closed | J588: 1 | K588: 12 | L588: No | M588: 0 | N588: 5 | O588: 400 | P588: 400 | Q588: Sep | R588: 9 | S588: Q3 | T588: Thursday | U588: =TRIM(CLEAN(tbl_Operations[[#This Row],[Location]])) -> Noida | V588: =TRIM(CLEAN(tbl_Operations[[#This Row],[Channel]])) -> Portal | W588: =TRIM(CLEAN(E588)) -> System Issue | X588: =PROPER(TRIM(CLEAN(C588))) -> It | Y588: =IF(J588<=K588,"Within SLA","SLA Breach") -> Within SLA | Z588: =IF(AND(F588="Critical",Y587="SLA Breach"),"Critical Risk","Normal") -> Normal | AA588: {=_xlfn.IFS( J588<=K588*0.5,"Excellent", J588<=K588,"Good", J588<=K588*1.5,"At Risk", TRUE,"Critical" )} -> Excellent | AB588: =IF(M588>0,"Reworked","No Rework") -> No Rework
A589: OPS-100337 | B589: 45890 | C589: Sales | D589: Unknown | E589: Access Request | F589: Medium | G589: Email | H589: Finance Ops | I589: Escalated | J589: 36 | K589: 24 | L589: Yes | M589: 2 | N589: 4 | O589: 280 | P589: 10080 | Q589: Aug | R589: 8 | S589: Q3 | T589: Thursday | U589: =TRIM(CLEAN(tbl_Operations[[#This Row],[Location]])) -> Unknown | V589: =TRIM(CLEAN(tbl_Operations[[#This Row],[Channel]])) -> Email | W589: =TRIM(CLEAN(E589)) -> Access Request | X589: =PROPER(TRIM(CLEAN(C589))) -> Sales | Y589: =IF(J589<=K589,"Within SLA","SLA Breach") -> SLA Breach | Z589: =IF(AND(F589="Critical",Y588="SLA Breach"),"Critical Risk","Normal") -> Normal | AA589: {=_xlfn.IFS( J589<=K589*0.5,"Excellent", J589<=K589,"Good", J589<=K589*1.5,"At Risk", TRUE,"Critical" )} -> At Risk | AB589: =IF(M589>0,"Reworked","No Rework") -> Reworked
A590: OPS-103493 | B590: 45806 | C590: HR | D590: Bengaluru | E590: Data Correction | F590: Critical | G590: Teams | H590: Vendor Management | I590: Closed | J590: 6.3 | K590: 4 | L590: Yes | M590: 0 | N590: 5 | O590: 450 | P590: 2835 | Q590: May | R590: 5 | S590: Q2 | T590: Thursday | U590: =TRIM(CLEAN(tbl_Operations[[#This Row],[Location]])) -> Bengaluru | V590: =TRIM(CLEAN(tbl_Operations[[#This Row],[Channel]])) -> Teams | W590: =TRIM(CLEAN(E590)) -> Data Correction | X590: =PROPER(TRIM(CLEAN(C590))) -> Hr | Y590: =IF(J590<=K590,"Within SLA","SLA Breach") -> SLA Breach | Z590: =IF(AND(F590="Critical",Y589="SLA Breach"),"Critical Risk","Normal") -> Critical Risk | AA590: {=_xlfn.IFS( J590<=K590*0.5,"Excellent", J590<=K590,"Good", J590<=K590*1.5,"At Risk", TRUE,"Critical" )} -> Critical | AB590: =IF(M590>0,"Reworked","No Rework") -> No Rework
A591: OPS-101310 | B591: 45815 | C591: IT | D591: Gurugram | E591: Employee Query | F591: Low | G591: Teams | H591: HR Ops | I591: Escalated | J591: 12.9 | K591: 48 | L591: No | M591: 2 | N591: 4.6 | O591: 450 | P591: 5805 | Q591: Jun | R591: 6 | S591: Q2 | T591: Saturday | U591: =TRIM(CLEAN(tbl_Operations[[#This Row],[Location]])) -> Gurugram | V591: =TRIM(CLEAN(tbl_Operations[[#This Row],[Channel]])) -> Teams | W591: =TRIM(CLEAN(E591)) -> Employee Query | X591: =PROPER(TRIM(CLEAN(C591))) -> It | Y591: =IF(J591<=K591,"Within SLA","SLA Breach") -> Within SLA | Z591: =IF(AND(F591="Critical",Y590="SLA Breach"),"Critical Risk","Normal") -> Normal | AA591: {=_xlfn.IFS( J591<=K591*0.5,"Excellent", J591<=K591,"Good", J591<=K591*1.5,"At Risk", TRUE,"Critical" )} -> Excellent | AB591: =IF(M591>0,"Reworked","No Rework") -> Reworked
...

Sheet MIS_KPI
A1: MIS KPI | B1: Value
A2: Total Tickets | B2: =COUNTA(tbl_Operations[Ticket_ID]) -> 5000
A3: Closed Tickets | B3: =COUNTIF(tbl_Operations[Status], "Closed") -> 3969
A4: Pending Tickets | B4: =COUNTIF(tbl_Operations[Status], "Pending") -> 429
A5: Escalated Tickets | B5: =COUNTIF(tbl_Operations[Status],"Escalated") -> 602
A6: Closure Rate % | B6: =B3/B2 -> 0.7938
A7: SLA Achievement % | B7: =COUNTIF(tbl_Operations[SLA_Status],"Within SLA")/B2 -> 0.854
A8: Avg Resolution Hours | B8: =AVERAGE(tbl_Operations[Resolution_Hours]) -> 12.79436
A9: Avg CSAT | B9: =AVERAGE(tbl_Operations[Customer_Satisfaction]) -> 4.4504024
A10: Total Operational Cost | B10: =SUM(tbl_Operations[Estimated_Cost]) -> 23042401
A11: Total Rework | B11: =SUM(tbl_Operations[Rework_Count]) -> 3152
A12: Rework Rate % | B12: =B11/B2 -> 0.6304
A13: Reworked Tickets | B13: =COUNTIF(tbl_Operations[Rework_Status],"Reworked") -> 2171
A14: Rework Ticket Rate % | B14: =B13/B2 -> 0.4342
A15: Total Rework Events | B15: =SUM(tbl_Operations[Rework_Count]) -> 3152

Sheet Team_Analysis
A1: Assigned Team | B1: Tickets | C1: Closed | D1: SLA Breaches | E1: SLA % | F1: Avg Resolution Hrs | G1: Rank
A2: MIS | B2: =COUNTIF(tbl_Operations[Assigned_Team],A2) -> 958 | C2: =COUNTIFS(tbl_Operations[Assigned_Team],A2,tbl_Operations[Status],"Closed") -> 782 | D2: =COUNTIFS(tbl_Operations[Assigned_Team],A2,tbl_Operations[SLA_Status],"SLA Breach") -> 129 | E2: =(B2-D2)/B2 -> 0.86534447 | F2: =AVERAGEIF(tbl_Operations[Assigned_Team],A2,tbl_Operations[Resolution_Hours]) -> 12.988205 | G2: =RANK(E2,$E$2:$E$6,0) -> 1
A3: Finance Ops | B3: =COUNTIF(tbl_Operations[Assigned_Team],A3) -> 949 | C3: =COUNTIFS(tbl_Operations[Assigned_Team],A3,tbl_Operations[Status],"Closed") -> 769 | D3: =COUNTIFS(tbl_Operations[Assigned_Team],A3,tbl_Operations[SLA_Status],"SLA Breach") -> 146 | E3: =(B3-D3)/B3 -> 0.84615385 | F3: =AVERAGEIF(tbl_Operations[Assigned_Team],A3,tbl_Operations[Resolution_Hours]) -> 12.447734 | G3: =RANK(E3,$E$2:$E$6,0) -> 4
A4: HR Ops | B4: =COUNTIF(tbl_Operations[Assigned_Team],A4) -> 1021 | C4: =COUNTIFS(tbl_Operations[Assigned_Team],A4,tbl_Operations[Status],"Closed") -> 803 | D4: =COUNTIFS(tbl_Operations[Assigned_Team],A4,tbl_Operations[SLA_Status],"SLA Breach") -> 144 | E4: =(B4-D4)/B4 -> 0.8589618 | F4: =AVERAGEIF(tbl_Operations[Assigned_Team],A4,tbl_Operations[Resolution_Hours]) -> 13.087953 | G4: =RANK(E4,$E$2:$E$6,0) -> 2
A5: IT Support | B5: =COUNTIF(tbl_Operations[Assigned_Team],A5) -> 961 | C5: =COUNTIFS(tbl_Operations[Assigned_Team],A5,tbl_Operations[Status],"Closed") -> 729 | D5: =COUNTIFS(tbl_Operations[Assigned_Team],A5,tbl_Operations[SLA_Status],"SLA Breach") -> 148 | E5: =(B5-D5)/B5 -> 0.84599376 | F5: =AVERAGEIF(tbl_Operations[Assigned_Team],A5,tbl_Operations[Resolution_Hours]) -> 13.013215 | G5: =RANK(E5,$E$2:$E$6,0) -> 5
A6: Vendor Management | B6: =COUNTIF(tbl_Operations[Assigned_Team],A6) -> 1066 | C6: =COUNTIFS(tbl_Operations[Assigned_Team],A6,tbl_Operations[Status],"Closed") -> 849 | D6: =COUNTIFS(tbl_Operations[Assigned_Team],A6,tbl_Operations[SLA_Status],"SLA Breach") -> 157 | E6: =(B6-D6)/B6 -> 0.85272045 | F6: =AVERAGEIF(tbl_Operations[Assigned_Team],A6,tbl_Operations[Resolution_Hours]) -> 12.533114 | G6: =RANK(E6,$E$2:$E$6,0) -> 3

Sheet BU_Analysis
A1: Business Unit | B1: Tickets | C1: Closed | D1: SLA Breaches | E1: Avg Resolution Hrs | F1: Total Cost
A2: Finance | B2: =COUNTIF(tbl_Operations[Business_Unit],A2) -> 683 | C2: =COUNTIFS(tbl_Operations[Business_Unit],A2,tbl_Operations[Status],"Closed") -> 539 | D2: =COUNTIFS(tbl_Operations[Business_Unit],A2,tbl_Operations[SLA_Status],"SLA Breach") -> 99 | E2: =AVERAGEIF(tbl_Operations[Business_Unit],A2,tbl_Operations[Resolution_Hours]) -> 12.862665 | F2: =SUMIF(tbl_Operations[Business_Unit],A2,tbl_Operations[Estimated_Cost]) -> 3161483
A3: HR | B3: =COUNTIF(tbl_Operations[Business_Unit],A3) -> 768 | C3: =COUNTIFS(tbl_Operations[Business_Unit],A3,tbl_Operations[Status],"Closed") -> 631 | D3: =COUNTIFS(tbl_Operations[Business_Unit],A3,tbl_Operations[SLA_Status],"SLA Breach") -> 97 | E3: =AVERAGEIF(tbl_Operations[Business_Unit],A3,tbl_Operations[Resolution_Hours]) -> 12.486719 | F3: =SUMIF(tbl_Operations[Business_Unit],A3,tbl_Operations[Estimated_Cost]) -> 3446642
A4: Sales | B4: =COUNTIF(tbl_Operations[Business_Unit],A4) -> 680 | C4: =COUNTIFS(tbl_Operations[Business_Unit],A4,tbl_Operations[Status],"Closed") -> 554 | D4: =COUNTIFS(tbl_Operations[Business_Unit],A4,tbl_Operations[SLA_Status],"SLA Breach") -> 96 | E4: =AVERAGEIF(tbl_Operations[Business_Unit],A4,tbl_Operations[Resolution_Hours]) -> 12.274559 | F4: =SUMIF(tbl_Operations[Business_Unit],A4,tbl_Operations[Estimated_Cost]) -> 2997714
A5: Operations | B5: =COUNTIF(tbl_Operations[Business_Unit],A5) -> 702 | C5: =COUNTIFS(tbl_Operations[Business_Unit],A5,tbl_Operations[Status],"Closed") -> 530 | D5: =COUNTIFS(tbl_Operations[Business_Unit],A5,tbl_Operations[SLA_Status],"SLA Breach") -> 104 | E5: =AVERAGEIF(tbl_Operations[Business_Unit],A5,tbl_Operations[Resolution_Hours]) -> 12.927066 | F5: =SUMIF(tbl_Operations[Business_Unit],A5,tbl_Operations[Estimated_Cost]) -> 3299592
A6: IT | B6: =COUNTIF(tbl_Operations[Business_Unit],A6) -> 715 | C6: =COUNTIFS(tbl_Operations[Business_Unit],A6,tbl_Operations[Status],"Closed") -> 576 | D6: =COUNTIFS(tbl_Operations[Business_Unit],A6,tbl_Operations[SLA_Status],"SLA Breach") -> 108 | E6: =AVERAGEIF(tbl_Operations[Business_Unit],A6,tbl_Operations[Resolution_Hours]) -> 12.914825 | F6: =SUMIF(tbl_Operations[Business_Unit],A6,tbl_Operations[Estimated_Cost]) -> 3301070
A7: Procurement | B7: =COUNTIF(tbl_Operations[Business_Unit],A7) -> 701 | C7: =COUNTIFS(tbl_Operations[Business_Unit],A7,tbl_Operations[Status],"Closed") -> 548 | D7: =COUNTIFS(tbl_Operations[Business_Unit],A7,tbl_Operations[SLA_Status],"SLA Breach") -> 109 | E7: =AVERAGEIF(tbl_Operations[Business_Unit],A7,tbl_Operations[Resolution_Hours]) -> 13.109986 | F7: =SUMIF(tbl_Operations[Business_Unit],A7,tbl_Operations[Estimated_Cost]) -> 3326307
A8: Customer Support | B8: =COUNTIF(tbl_Operations[Business_Unit],A8) -> 751 | C8: =COUNTIFS(tbl_Operations[Business_Unit],A8,tbl_Operations[Status],"Closed") -> 591 | D8: =COUNTIFS(tbl_Operations[Business_Unit],A8,tbl_Operations[SLA_Status],"SLA Breach") -> 117 | E8: =AVERAGEIF(tbl_Operations[Business_Unit],A8,tbl_Operations[Resolution_Hours]) -> 12.984154 | F8: =SUMIF(tbl_Operations[Business_Unit],A8,tbl_Operations[Estimated_Cost]) -> 3509593

Sheet Monthly_Analysis
A1: Month | B1: Tickets | C1: Closed | D1: SLA Breaches | E1: SLA % | F1: Avg Resolution Hrs | G1: Ticket MoM % | H1: SLA MoM Change
A2: Jan | B2: =COUNTIF(tbl_Operations[Month],A2) -> 420 | C2: =COUNTIFS(tbl_Operations[Month],A2,tbl_Operations[Status],"Closed") -> 346 | D2: =COUNTIFS(tbl_Operations[Month],A2,tbl_Operations[SLA_Status],"SLA Breach") -> 75 | E2: =(B2-D2)/B2 -> 0.82142857 | F2: =AVERAGEIF(tbl_Operations[Month],A2,tbl_Operations[Resolution_Hours]) -> 13.212381
A3: Feb | B3: =COUNTIF(tbl_Operations[Month],A3) -> 392 | C3: =COUNTIFS(tbl_Operations[Month],A3,tbl_Operations[Status],"Closed") -> 312 | D3: =COUNTIFS(tbl_Operations[Month],A3,tbl_Operations[SLA_Status],"SLA Breach") -> 54 | E3: =(B3-D3)/B3 -> 0.8622449 | F3: =AVERAGEIF(tbl_Operations[Month],A3,tbl_Operations[Resolution_Hours]) -> 12.666071 | G3: =(B3/B2)-1 -> -0.066666667 | H3: =E3-E2 -> 0.040816327
A4: Mar | B4: =COUNTIF(tbl_Operations[Month],A4) -> 404 | C4: =COUNTIFS(tbl_Operations[Month],A4,tbl_Operations[Status],"Closed") -> 320 | D4: =COUNTIFS(tbl_Operations[Month],A4,tbl_Operations[SLA_Status],"SLA Breach") -> 66 | E4: =(B4-D4)/B4 -> 0.83663366 | F4: =AVERAGEIF(tbl_Operations[Month],A4,tbl_Operations[Resolution_Hours]) -> 12.726238 | G4: =(B4/B3)-1 -> 0.030612245 | H4: =E4-E3 -> -0.025611235
A5: Apr | B5: =COUNTIF(tbl_Operations[Month],A5) -> 433 | C5: =COUNTIFS(tbl_Operations[Month],A5,tbl_Operations[Status],"Closed") -> 339 | D5: =COUNTIFS(tbl_Operations[Month],A5,tbl_Operations[SLA_Status],"SLA Breach") -> 60 | E5: =(B5-D5)/B5 -> 0.86143187 | F5: =AVERAGEIF(tbl_Operations[Month],A5,tbl_Operations[Resolution_Hours]) -> 12.642725 | G5: =(B5/B4)-1 -> 0.071782178 | H5: =E5-E4 -> 0.024798207
A6: May | B6: =COUNTIF(tbl_Operations[Month],A6) -> 441 | C6: =COUNTIFS(tbl_Operations[Month],A6,tbl_Operations[Status],"Closed") -> 351 | D6: =COUNTIFS(tbl_Operations[Month],A6,tbl_Operations[SLA_Status],"SLA Breach") -> 75 | E6: =(B6-D6)/B6 -> 0.82993197 | F6: =AVERAGEIF(tbl_Operations[Month],A6,tbl_Operations[Resolution_Hours]) -> 12.989116 | G6: =(B6/B5)-1 -> 0.018475751 | H6: =E6-E5 -> -0.031499898
A7: Jun | B7: =COUNTIF(tbl_Operations[Month],A7) -> 440 | C7: =COUNTIFS(tbl_Operations[Month],A7,tbl_Operations[Status],"Closed") -> 342 | D7: =COUNTIFS(tbl_Operations[Month],A7,tbl_Operations[SLA_Status],"SLA Breach") -> 60 | E7: =(B7-D7)/B7 -> 0.86363636 | F7: =AVERAGEIF(tbl_Operations[Month],A7,tbl_Operations[Resolution_Hours]) -> 12.924545 | G7: =(B7/B6)-1 -> -0.0022675737 | H7: =E7-E6 -> 0.033704391
A8: Jul | B8: =COUNTIF(tbl_Operations[Month],A8) -> 375 | C8: =COUNTIFS(tbl_Operations[Month],A8,tbl_Operations[Status],"Closed") -> 299 | D8: =COUNTIFS(tbl_Operations[Month],A8,tbl_Operations[SLA_Status],"SLA Breach") -> 57 | E8: =(B8-D8)/B8 -> 0.848 | F8: =AVERAGEIF(tbl_Operations[Month],A8,tbl_Operations[Resolution_Hours]) -> 13.410133 | G8: =(B8/B7)-1 -> -0.14772727 | H8: =E8-E7 -> -0.015636364
A9: Aug | B9: =COUNTIF(tbl_Operations[Month],A9) -> 441 | C9: =COUNTIFS(tbl_Operations[Month],A9,tbl_Operations[Status],"Closed") -> 362 | D9: =COUNTIFS(tbl_Operations[Month],A9,tbl_Operations[SLA_Status],"SLA Breach") -> 54 | E9: =(B9-D9)/B9 -> 0.87755102 | F9: =AVERAGEIF(tbl_Operations[Month],A9,tbl_Operations[Resolution_Hours]) -> 12.636961 | G9: =(B9/B8)-1 -> 0.176 | H9: =E9-E8 -> 0.02955102
A10: Sep | B10: =COUNTIF(tbl_Operations[Month],A10) -> 395 | C10: =COUNTIFS(tbl_Operations[Month],A10,tbl_Operations[Status],"Closed") -> 312 | D10: =COUNTIFS(tbl_Operations[Month],A10,tbl_Operations[SLA_Status],"SLA Breach") -> 59 | E10: =(B10-D10)/B10 -> 0.85063291 | F10: =AVERAGEIF(tbl_Operations[Month],A10,tbl_Operations[Resolution_Hours]) -> 13.007342 | G10: =(B10/B9)-1 -> -0.10430839 | H10: =E10-E9 -> -0.026918109
A11: Oct | B11: =COUNTIF(tbl_Operations[Month],A11) -> 418 | C11: =COUNTIFS(tbl_Operations[Month],A11,tbl_Operations[Status],"Closed") -> 324 | D11: =COUNTIFS(tbl_Operations[Month],A11,tbl_Operations[SLA_Status],"SLA Breach") -> 58 | E11: =(B11-D11)/B11 -> 0.86124402 | F11: =AVERAGEIF(tbl_Operations[Month],A11,tbl_Operations[Resolution_Hours]) -> 12.30622 | G11: =(B11/B10)-1 -> 0.058227848 | H11: =E11-E10 -> 0.010611108
A12: Nov | B12: =COUNTIF(tbl_Operations[Month],A12) -> 411 | C12: =COUNTIFS(tbl_Operations[Month],A12,tbl_Operations[Status],"Closed") -> 331 | D12: =COUNTIFS(tbl_Operations[Month],A12,tbl_Operations[SLA_Status],"SLA Breach") -> 55 | E12: =(B12-D12)/B12 -> 0.86618005 | F12: =AVERAGEIF(tbl_Operations[Month],A12,tbl_Operations[Resolution_Hours]) -> 12.318978 | G12: =(B12/B11)-1 -> -0.016746411 | H12: =E12-E11 -> 0.0049360295
A13: Dec | B13: =COUNTIF(tbl_Operations[Month],A13) -> 430 | C13: =COUNTIFS(tbl_Operations[Month],A13,tbl_Operations[Status],"Closed") -> 331 | D13: =COUNTIFS(tbl_Operations[Month],A13,tbl_Operations[SLA_Status],"SLA Breach") -> 57 | E13: =(B13-D13)/B13 -> 0.86744186 | F13: =AVERAGEIF(tbl_Operations[Month],A13,tbl_Operations[Resolution_Hours]) -> 12.744419 | G13: =(B13/B12)-1 -> 0.04622871 | H13: =E13-E12 -> 0.0012618118

Sheet Target_Analysis
A1: =IF(COUNTIF(E5:E7,"Not Met")=0,"All Targets Met","Management Attention Required") -> Management Attention Required
A4: KPI | B4: Target | C4: Actual | D4: Variance | E4: Status | F4: Management Comment
A5: SLA Achievement % | B5: 0.9 | C5: =MIS_KPI!B7 -> 0.854 | D5: =C5-B5 -> -0.046 | E5: =IF(C5>=B5,"Met","Not Met") -> Not Met | F5: =IF(E5="Met","Target achieved","Action required") -> Action required
A6: Closure Rate % | B6: 0.8 | C6: =MIS_KPI!B6 -> 0.7938 | D6: =C6-B6 -> -0.0062 | E6: =IF(C6>=B6,"Met","Not Met") -> Not Met | F6: =IF(E6="Met","Target achieved","Action required") -> Action required
A7: Avg Resolution Hours | B7: 12 | C7: =MIS_KPI!B8 -> 12.79436 | D7: =B7-C7 -> -0.79436 | E7: =IF(C7<=B7,"Met","Not Met") -> Not Met | F7: =IF(E7="Met","Target achieved","Action required") -> Action required

Sheet Pivot_BU
A3: SLA_Breached | B3: (All)
B5: Column Labels
B6: SLA Breach | D6: Within SLA | F6: Total Count of Ticket_ID | G6: Total Avg Resolution Hrs
A7: Row Labels | B7: Count of Ticket_ID | C7: Avg Resolution Hrs | D7: Count of Ticket_ID | E7: Avg Resolution Hrs
A8: Customer Support | B8: 0.15579228 | C8: 22.75812 | D8: 0.84420772 | E8: 11.180442 | F8: 1 | G8: 12.984154
A9: Finance | B9: 0.14494876 | C9: 25.187879 | D9: 0.85505124 | E9: 10.773288 | F9: 1 | G9: 12.862665
A10: Hr | B10: 0.12630208 | C10: 22.891753 | D10: 0.87369792 | E10: 10.982563 | F10: 1 | G10: 12.486719
A11: It | B11: 0.15104895 | C11: 24.708333 | D11: 0.84895105 | E11: 10.816474 | F11: 1 | G11: 12.914825
A12: Operations | B12: 0.14814815 | C12: 23.268269 | D12: 0.85185185 | E12: 11.128595 | F12: 1 | G12: 12.927066
A13: Procurement | B13: 0.15549215 | C13: 24.36055 | D13: 0.84450785 | E13: 11.038514 | F13: 1 | G13: 13.109986
A14: Sales | B14: 0.14117647 | C14: 21.396875 | D14: 0.85882353 | E14: 10.775 | F14: 1 | G14: 12.274559
A15: Grand Total | B15: 0.146 | C15: 23.526849 | D15: 0.854 | E15: 10.959532 | F15: 1 | G15: 12.79436

Sheet MIS_Dashboard
A1: OPERATIONS MIS PERFORMANCE DASHBOARD
A3: Annual Operations Performance | FY2025
A5: TOTAL TICKETS | C5: CLOSURE RATE | E5: SLA ACHIEVEMENT | G5: AVG RESOLUTION | I5: AVG CSAT | K5: REWORK RATE | M5: OPERATIONAL COST
A9: =MIS_KPI!B2 -> 5000 | C9: =MIS_KPI!B6 -> 0.7938 | E9: =MIS_KPI!B7 -> 0.854 | G9: =MIS_KPI!B8 -> 12.79436 | I9: =MIS_KPI!B9 -> 4.4504024 | K9: =MIS_KPI!B13/MIS_KPI!B2 -> 0.4342 | M9: =MIS_KPI!B10 -> 23042401
